Workbook

Sheet Inputs
A1: Scenario Selection | B1: Analysis_Start | C1: Analysis_Months | D1: GLA_sqft | E1: Base_Rent_psf_pa | F1: Annual_Rent_Growth_pct | G1: Free_Rent_Months | H1: Lease_Term_Months | I1: Downtime_Months | J1: Expense_Base_psf_pa | K1: Expense_Growth_pct | L1: CAM_Recovery_pct | M1: Bad_Debt_pct_of_Rent | N1: TI_psf | O1: LC_pct_of_Year1_Rent | P1: TI_Amort_Years | Q1: LC_Amort_Years | R1: Debt_Balance | S1: Reference_Rate_pct | T1: Spread_pct | U1: Hedge_pct_of_Debt | V1: Hedge_Fixed_Rate_pct
A2: 文本/标识 | B2: 分析起始日 | C2: 分析月数 | D2: GLA(平方英尺) | E2: 首年租金($/psf/年) | F2: 租金年增长率 | G2: 免租(月) | H2: 租期(月) | I2: 起租前空置(月) | J2: 费用基准($/psf/年) | K2: 费用年增长率 | L2: 可回收比例 | M2: 坏账率(对租金+Recoveries) | N2: TI($/psf) | O2: LC(首年租金%) | P2: TI摊销(年) | Q2: LC摊销(年) | R2: 债务余额 | S2: 参考利率 | T2: 利差 | U2: 对冲比例 | V2: 对冲固定利率
A3: Base | B3: =INDEX($B$5:$V$7, MATCH($A$3, $A$5:$A$7, 0),MATCH(B$1,$B$1:$V$1,0)) -> 45658 | C3: =INDEX($B$5:$V$7, MATCH($A$3, $A$5:$A$7, 0),MATCH(C$1,$B$1:$V$1,0)) -> 12 | D3: =INDEX($B$5:$V$7, MATCH($A$3, $A$5:$A$7, 0),MATCH(D$1,$B$1:$V$1,0)) -> 10000 | E3: =INDEX($B$5:$V$7, MATCH($A$3, $A$5:$A$7, 0),MATCH(E$1,$B$1:$V$1,0)) -> 50 | F3: =INDEX($B$5:$V$7, MATCH($A$3, $A$5:$A$7, 0),MATCH(F$1,$B$1:$V$1,0)) -> 0.03 | G3: =INDEX($B$5:$V$7, MATCH($A$3, $A$5:$A$7, 0),MATCH(G$1,$B$1:$V$1,0)) -> 1 | H3: =INDEX($B$5:$V$7, MATCH($A$3, $A$5:$A$7, 0),MATCH(H$1,$B$1:$V$1,0)) -> 60 | I3: =INDEX($B$5:$V$7, MATCH($A$3, $A$5:$A$7, 0),MATCH(I$1,$B$1:$V$1,0)) -> 1 | ... V3: =INDEX($B$5:$V$7, MATCH($A$3, $A$5:$A$7, 0),MATCH(V$1,$B$1:$V$1,0)) -> 0.055
A5: Base | B5: 45658 | C5: 12 | D5: 10000 | E5: 50 | F5: 0.03 | G5: 1 | H5: 60 | I5: 1 | J5: 12 | K5: 0.025 | L5: 0.8 | M5: 0.01 | N5: 20 | O5: 0.05 | P5: 5 | Q5: 5 | R5: 5000000 | S5: 0.05 | T5: 0.02 | U5: 0.5 | V5: 0.055
A6: Upside | B6: =$B$5 -> 45658 | C6: =$C$5 -> 12 | D6: =$D$5 -> 10000 | E6: =$E$5 -> 50 | F6: 0.05 | G6: =$G$5 -> 1 | H6: =$H$5 -> 60 | I6: 1 | J6: =$J$5 -> 12 | K6: 0.015 | L6: 0.9 | M6: 0.005 | N6: =$N$5 -> 20 | O6: =$O$5 -> 0.05 | P6: =$P$5 -> 5 | Q6: =$Q$5 -> 5 | R6: =$R$5 -> 5000000 | S6: 0.05 | T6: =$T$5 -> 0.02 | U6: =$U$5 -> 0.5 | V6: =$V$5 -> 0.055
A7: Downside | B7: =$B$5 -> 45658 | C7: =$C$5 -> 12 | D7: =$D$5 -> 10000 | E7: =$E$5 -> 50 | F7: 0 | G7: =$G$5 -> 1 | H7: =$H$5 -> 60 | I7: 2 | J7: =$J$5 -> 12 | K7: 0.035 | L7: 0.7 | M7: 0.02 | N7: =$N$5 -> 20 | O7: =$O$5 -> 0.05 | P7: =$P$5 -> 5 | Q7: =$Q$5 -> 5 | R7: =$R$5 -> 5000000 | S7: 0.06 | T7: =$T$5 -> 0.02 | U7: =$U$5 -> 0.5 | V7: =$V$5 -> 0.055
A10: Sensitivity
A11: OVR_RG_0bps | B11: =$B$5 -> 45658 | C11: =$C$5 -> 12 | D11: =$D$5 -> 10000 | E11: =$E$5 -> 50 | F11: 0 | G11: =$G$5 -> 1 | H11: =$H$5 -> 60 | I11: =$I$5 -> 1 | J11: =$J$5 -> 12 | K11: =$K$5 -> 0.025 | L11: =$L$5 -> 0.8 | M11: =$M$5 -> 0.01 | N11: =$N$5 -> 20 | O11: =$O$5 -> 0.05 | P11: =$P$5 -> 5 | Q11: =$Q$5 -> 5 | R11: =$R$5 -> 5000000 | S11: =$S$5 -> 0.05 | T11: =$T$5 -> 0.02 | U11: =$U$5 -> 0.5 | V11: =$V$5 -> 0.055
A12: OVR_RG_2bps | B12: =$B$5 -> 45658 | C12: =$C$5 -> 12 | D12: =$D$5 -> 10000 | E12: =$E$5 -> 50 | F12: 0.02 | G12: =$G$5 -> 1 | H12: =$H$5 -> 60 | I12: =$I$5 -> 1 | J12: =$J$5 -> 12 | K12: =$K$5 -> 0.025 | L12: =$L$5 -> 0.8 | M12: =$M$5 -> 0.01 | N12: =$N$5 -> 20 | O12: =$O$5 -> 0.05 | P12: =$P$5 -> 5 | Q12: =$Q$5 -> 5 | R12: =$R$5 -> 5000000 | S12: =$S$5 -> 0.05 | T12: =$T$5 -> 0.02 | U12: =$U$5 -> 0.5 | V12: =$V$5 -> 0.055
A13: OVR_RG_3bps | B13: =$B$5 -> 45658 | C13: =$C$5 -> 12 | D13: =$D$5 -> 10000 | E13: =$E$5 -> 50 | F13: 0.03 | G13: =$G$5 -> 1 | H13: =$H$5 -> 60 | I13: =$I$5 -> 1 | J13: =$J$5 -> 12 | K13: =$K$5 -> 0.025 | L13: =$L$5 -> 0.8 | M13: =$M$5 -> 0.01 | N13: =$N$5 -> 20 | O13: =$O$5 -> 0.05 | P13: =$P$5 -> 5 | Q13: =$Q$5 -> 5 | R13: =$R$5 -> 5000000 | S13: =$S$5 -> 0.05 | T13: =$T$5 -> 0.02 | U13: =$U$5 -> 0.5 | V13: =$V$5 -> 0.055
A14: OVR_RG_4bps | B14: =$B$5 -> 45658 | C14: =$C$5 -> 12 | D14: =$D$5 -> 10000 | E14: =$E$5 -> 50 | F14: 0.04 | G14: =$G$5 -> 1 | H14: =$H$5 -> 60 | I14: =$I$5 -> 1 | J14: =$J$5 -> 12 | K14: =$K$5 -> 0.025 | L14: =$L$5 -> 0.8 | M14: =$M$5 -> 0.01 | N14: =$N$5 -> 20 | O14: =$O$5 -> 0.05 | P14: =$P$5 -> 5 | Q14: =$Q$5 -> 5 | R14: =$R$5 -> 5000000 | S14: =$S$5 -> 0.05 | T14: =$T$5 -> 0.02 | U14: =$U$5 -> 0.5 | V14: =$V$5 -> 0.055
A15: OVR_RG_5bps | B15: =$B$5 -> 45658 | C15: =$C$5 -> 12 | D15: =$D$5 -> 10000 | E15: =$E$5 -> 50 | F15: 0.05 | G15: =$G$5 -> 1 | H15: =$H$5 -> 60 | I15: =$I$5 -> 1 | J15: =$J$5 -> 12 | K15: =$K$5 -> 0.025 | L15: =$L$5 -> 0.8 | M15: =$M$5 -> 0.01 | N15: =$N$5 -> 20 | O15: =$O$5 -> 0.05 | P15: =$P$5 -> 5 | Q15: =$Q$5 -> 5 | R15: =$R$5 -> 5000000 | S15: =$S$5 -> 0.05 | T15: =$T$5 -> 0.02 | U15: =$U$5 -> 0.5 | V15: =$V$5 -> 0.055
A16: OVR_RG_6bps | B16: =$B$5 -> 45658 | C16: =$C$5 -> 12 | D16: =$D$5 -> 10000 | E16: =$E$5 -> 50 | F16: 0.06 | G16: =$G$5 -> 1 | H16: =$H$5 -> 60 | I16: =$I$5 -> 1 | J16: =$J$5 -> 12 | K16: =$K$5 -> 0.025 | L16: =$L$5 -> 0.8 | M16: =$M$5 -> 0.01 | N16: =$N$5 -> 20 | O16: =$O$5 -> 0.05 | P16: =$P$5 -> 5 | Q16: =$Q$5 -> 5 | R16: =$R$5 -> 5000000 | S16: =$S$5 -> 0.05 | T16: =$T$5 -> 0.02 | U16: =$U$5 -> 0.5 | V16: =$V$5 -> 0.055
A17: OVR_DT_0m | B17: =$B$5 -> 45658 | C17: =$C$5 -> 12 | D17: =$D$5 -> 10000 | E17: =$E$5 -> 50 | F17: =$F$5 -> 0.03 | G17: =$G$5 -> 1 | H17: =$H$5 -> 60 | I17: 0 | J17: =$J$5 -> 12 | K17: =$K$5 -> 0.025 | L17: =$L$5 -> 0.8 | M17: =$M$5 -> 0.01 | N17: =$N$5 -> 20 | O17: =$O$5 -> 0.05 | P17: =$P$5 -> 5 | Q17: =$Q$5 -> 5 | R17: =$R$5 -> 5000000 | S17: =$S$5 -> 0.05 | T17: =$T$5 -> 0.02 | U17: =$U$5 -> 0.5 | V17: =$V$5 -> 0.055
A18: OVR_DT_1m | B18: =$B$5 -> 45658 | C18: =$C$5 -> 12 | D18: =$D$5 -> 10000 | E18: =$E$5 -> 50 | F18: =$F$5 -> 0.03 | G18: =$G$5 -> 1 | H18: =$H$5 -> 60 | I18: 1 | J18: =$J$5 -> 12 | K18: =$K$5 -> 0.025 | L18: =$L$5 -> 0.8 | M18: =$M$5 -> 0.01 | N18: =$N$5 -> 20 | O18: =$O$5 -> 0.05 | P18: =$P$5 -> 5 | Q18: =$Q$5 -> 5 | R18: =$R$5 -> 5000000 | S18: =$S$5 -> 0.05 | T18: =$T$5 -> 0.02 | U18: =$U$5 -> 0.5 | V18: =$V$5 -> 0.055
A19: OVR_DT_2m | B19: =$B$5 -> 45658 | C19: =$C$5 -> 12 | D19: =$D$5 -> 10000 | E19: =$E$5 -> 50 | F19: =$F$5 -> 0.03 | G19: =$G$5 -> 1 | H19: =$H$5 -> 60 | I19: 2 | J19: =$J$5 -> 12 | K19: =$K$5 -> 0.025 | L19: =$L$5 -> 0.8 | M19: =$M$5 -> 0.01 | N19: =$N$5 -> 20 | O19: =$O$5 -> 0.05 | P19: =$P$5 -> 5 | Q19: =$Q$5 -> 5 | R19: =$R$5 -> 5000000 | S19: =$S$5 -> 0.05 | T19: =$T$5 -> 0.02 | U19: =$U$5 -> 0.5 | V19: =$V$5 -> 0.055
A20: OVR_DT_3m | B20: =$B$5 -> 45658 | C20: =$C$5 -> 12 | D20: =$D$5 -> 10000 | E20: =$E$5 -> 50 | F20: =$F$5 -> 0.03 | G20: =$G$5 -> 1 | H20: =$H$5 -> 60 | I20: 3 | J20: =$J$5 -> 12 | K20: =$K$5 -> 0.025 | L20: =$L$5 -> 0.8 | M20: =$M$5 -> 0.01 | N20: =$N$5 -> 20 | O20: =$O$5 -> 0.05 | P20: =$P$5 -> 5 | Q20: =$Q$5 -> 5 | R20: =$R$5 -> 5000000 | S20: =$S$5 -> 0.05 | T20: =$T$5 -> 0.02 | U20: =$U$5 -> 0.5 | V20: =$V$5 -> 0.055
A21: OVR_EG_1 | B21: =$B$5 -> 45658 | C21: =$C$5 -> 12 | D21: =$D$5 -> 10000 | E21: =$E$5 -> 50 | F21: =$F$5 -> 0.03 | G21: =$G$5 -> 1 | H21: =$H$5 -> 60 | I21: =$I$5 -> 1 | J21: =$J$5 -> 12 | K21: 0.015 | L21: =$L$5 -> 0.8 | M21: =$M$5 -> 0.01 | N21: =$N$5 -> 20 | O21: =$O$5 -> 0.05 | P21: =$P$5 -> 5 | Q21: =$Q$5 -> 5 | R21: =$R$5 -> 5000000 | S21: =$S$5 -> 0.05 | T21: =$T$5 -> 0.02 | U21: =$U$5 -> 0.5 | V21: =$V$5 -> 0.055
A22: OVR_EG_2 | B22: =$B$5 -> 45658 | C22: =$C$5 -> 12 | D22: =$D$5 -> 10000 | E22: =$E$5 -> 50 | F22: =$F$5 -> 0.03 | G22: =$G$5 -> 1 | H22: =$H$5 -> 60 | I22: =$I$5 -> 1 | J22: =$J$5 -> 12 | K22: 0.025 | L22: =$L$5 -> 0.8 | M22: =$M$5 -> 0.01 | N22: =$N$5 -> 20 | O22: =$O$5 -> 0.05 | P22: =$P$5 -> 5 | Q22: =$Q$5 -> 5 | R22: =$R$5 -> 5000000 | S22: =$S$5 -> 0.05 | T22: =$T$5 -> 0.02 | U22: =$U$5 -> 0.5 | V22: =$V$5 -> 0.055
A23: OVR_EG_3 | B23: =$B$5 -> 45658 | C23: =$C$5 -> 12 | D23: =$D$5 -> 10000 | E23: =$E$5 -> 50 | F23: =$F$5 -> 0.03 | G23: =$G$5 -> 1 | H23: =$H$5 -> 60 | I23: =$I$5 -> 1 | J23: =$J$5 -> 12 | K23: 0.035 | L23: =$L$5 -> 0.8 | M23: =$M$5 -> 0.01 | N23: =$N$5 -> 20 | O23: =$O$5 -> 0.05 | P23: =$P$5 -> 5 | Q23: =$Q$5 -> 5 | R23: =$R$5 -> 5000000 | S23: =$S$5 -> 0.05 | T23: =$T$5 -> 0.02 | U23: =$U$5 -> 0.5 | V23: =$V$5 -> 0.055
A24: OVR_RR_4 | B24: =$B$5 -> 45658 | C24: =$C$5 -> 12 | D24: =$D$5 -> 10000 | E24: =$E$5 -> 50 | F24: =$F$5 -> 0.03 | G24: =$G$5 -> 1 | H24: =$H$5 -> 60 | I24: =$I$5 -> 1 | J24: =$J$5 -> 12 | K24: =$K$5 -> 0.025 | L24: =$L$5 -> 0.8 | M24: =$M$5 -> 0.01 | N24: =$N$5 -> 20 | O24: =$O$5 -> 0.05 | P24: =$P$5 -> 5 | Q24: =$Q$5 -> 5 | R24: =$R$5 -> 5000000 | S24: 0.04 | T24: =$T$5 -> 0.02 | U24: =$U$5 -> 0.5 | V24: =$V$5 -> 0.055
A25: OVR_RR_5 | B25: =$B$5 -> 45658 | C25: =$C$5 -> 12 | D25: =$D$5 -> 10000 | E25: =$E$5 -> 50 | F25: =$F$5 -> 0.03 | G25: =$G$5 -> 1 | H25: =$H$5 -> 60 | I25: =$I$5 -> 1 | J25: =$J$5 -> 12 | K25: =$K$5 -> 0.025 | L25: =$L$5 -> 0.8 | M25: =$M$5 -> 0.01 | N25: =$N$5 -> 20 | O25: =$O$5 -> 0.05 | P25: =$P$5 -> 5 | Q25: =$Q$5 -> 5 | R25: =$R$5 -> 5000000 | S25: 0.05 | T25: =$T$5 -> 0.02 | U25: =$U$5 -> 0.5 | V25: =$V$5 -> 0.055
A26: OVR_RR_6 | B26: =$B$5 -> 45658 | C26: =$C$5 -> 12 | D26: =$D$5 -> 10000 | E26: =$E$5 -> 50 | F26: =$F$5 -> 0.03 | G26: =$G$5 -> 1 | H26: =$H$5 -> 60 | I26: =$I$5 -> 1 | J26: =$J$5 -> 12 | K26: =$K$5 -> 0.025 | L26: =$L$5 -> 0.8 | M26: =$M$5 -> 0.01 | N26: =$N$5 -> 20 | O26: =$O$5 -> 0.05 | P26: =$P$5 -> 5 | Q26: =$Q$5 -> 5 | R26: =$R$5 -> 5000000 | S26: 0.06 | T26: =$T$5 -> 0.02 | U26: =$U$5 -> 0.5 | V26: =$V$5 -> 0.055
G28: NOI_pre | H28: AFFO | J28: NOI_pre | K28: AFFO | M28: NOI_pre | N28: AFFO | T28: NOI_pre | U28: AFFO
G29: =Summary!L14 -> 386003.47 | H29: =Summary!Q14 -> 8920.1337 | J29: =Summary!L14 -> 386003.47 | K29: =Summary!Q14 -> 8920.1337 | M29: =Summary!L14 -> 386003.47 | N29: =Summary!Q14 -> 8920.1337 | T29: =Summary!L14 -> 386003.47 | U29: =Summary!Q14 -> 8920.1337
F30: 0 | G30: 379335.28 | H30: 2251.9418 | I30: 0 | J30: 435275.2 | K30: 58191.867 | L30: 0.015 | M30: 386117.05 | N30: 9033.7199 | S30: 0.03 | T30: 386003.47 | U30: 58920.134
F31: 0.02 | G31: 383788.42 | H31: 6705.0904 | I31: 1 | J31: 386003.47 | K31: 8920.1337 | L31: 0.025 | M31: 386003.47 | N31: 8920.1337 | S31: 0.04 | T31: 386003.47 | U31: 33920.134
F32: 0.03 | G32: 386003.47 | H32: 8920.1337 | I32: 2 | J32: 336613.43 | K32: -40469.898 | L32: 0.035 | M32: 385890.28 | N32: 8806.9456 | S32: 0.05 | T32: 386003.47 | U32: 8920.1337
F33: 0.04 | G33: 388210.97 | H33: 11127.637 | I33: 3 | J33: 287104.82 | K33: -89978.514 | S33: 0.06 | T33: 386003.47 | U33: -16079.866
F34: 0.05 | G34: 390411.04 | H34: 13327.707 | S34: 0.07 | T34: 386003.47 | U34: -41079.866
F35: 0.06 | G35: 392603.78 | H35: 15520.449

Sheet CF_Scenarios
A1: Scenario Selection | B1: Month_Index | C1: Month_Start | D1: Occupied | E1: FreeRent | F1: Rent_psf_pa | G1: Base_Rent | H1: Expense_psf_pa | I1: OpEx | J1: Recoveries | K1: Bad_Debt | L1: NOI_pre_Amort | M1: TI_Amort | N1: LC_Amort | O1: NOI | P1: Interest_Expense | Q1: AFFO | R1: Quarter
A2: Base | B2: 1 | C2: 45658 | D2: 0 | E2: 0 | F2: 50 | G2: 0 | H2: 12 | I2: 10000 | J2: 0 | K2: 0 | L2: -10000 | M2: -3333.3333 | N2: -2048.6111 | O2: -15381.944 | P2: -26041.667 | Q2: -41423.611 | R2: Q1
A3: Base | B3: 2 | C3: 45689 | D3: 1 | E3: 1 | F3: 50.123313 | G3: 0 | H3: 12.024718 | I3: 10020.598 | J3: 8016.4787 | K3: -80.164787 | L3: -2084.2845 | M3: -3333.3333 | N3: -2048.6111 | O3: -7466.2289 | P3: -26041.667 | Q3: -33507.896 | R3: Q1
A4: Base | B4: 3 | C4: 45717 | D4: 1 | E4: 0 | F4: 50.246931 | G4: 41872.443 | H4: 12.049487 | I4: 10041.239 | J4: 8032.9913 | K4: -499.05434 | L4: 39365.14 | M4: -3333.3333 | N4: -2048.6111 | O4: 33983.196 | P4: -26041.667 | Q4: 7941.5293 | R4: Q1
A5: Base | B5: 4 | C5: 45748 | D5: 1 | E5: 0 | F5: 50.370854 | G5: 41975.711 | H5: 12.074307 | I5: 10061.922 | J5: 8049.538 | K5: -500.25249 | L5: 39463.074 | M5: -3333.3333 | N5: -2048.6111 | O5: 34081.13 | P5: -26041.667 | Q5: 8039.4632 | R5: Q2
A6: Base | B6: 5 | C6: 45778 | D6: 1 | E6: 0 | F6: 50.495082 | G6: 42079.235 | H6: 12.099178 | I6: 10082.648 | J6: 8066.1187 | K6: -501.45353 | L6: 39561.252 | M6: -3333.3333 | N6: -2048.6111 | O6: 34179.307 | P6: -26041.667 | Q6: 8137.6404 | R6: Q2
A7: Base | B7: 6 | C7: 45809 | D7: 1 | E7: 0 | F7: 50.619616 | G7: 42183.013 | H7: 12.1241 | I7: 10103.417 | J7: 8082.7336 | K7: -502.65747 | L7: 39659.673 | M7: -3333.3333 | N7: -2048.6111 | O7: 34277.728 | P7: -26041.667 | Q7: 8236.0615 | R7: Q2
A8: Base | B8: 7 | C8: 45839 | D8: 1 | E8: 0 | F8: 50.744458 | G8: 42287.048 | H8: 12.149074 | I8: 10124.228 | J8: 8099.3827 | K8: -503.86431 | L8: 39758.338 | M8: -3333.3333 | N8: -2048.6111 | O8: 34376.394 | P8: -26041.667 | Q8: 8334.7271 | R8: Q3
A9: Base | B9: 8 | C9: 45870 | D9: 1 | E9: 0 | F9: 50.869607 | G9: 42391.339 | H9: 12.174099 | I9: 10145.083 | J9: 8116.0661 | K9: -505.07406 | L9: 39857.249 | M9: -3333.3333 | N9: -2048.6111 | O9: 34475.304 | P9: -26041.667 | Q9: 8433.6378 | R9: Q3
A10: Base | B10: 9 | C10: 45901 | D10: 1 | E10: 0 | F10: 50.995066 | G10: 42495.888 | H10: 12.199176 | I10: 10165.98 | J10: 8132.7839 | K10: -506.28672 | L10: 39956.405 | M10: -3333.3333 | N10: -2048.6111 | O10: 34574.461 | P10: -26041.667 | Q10: 8532.7941 | R10: Q3
A11: Base | B11: 10 | C11: 45931 | D11: 1 | E11: 0 | F11: 51.120833 | G11: 42600.694 | H11: 12.224304 | I11: 10186.92 | J11: 8149.5361 | K11: -507.5023 | L11: 40055.808 | M11: -3333.3333 | N11: -2048.6111 | O11: 34673.863 | P11: -26041.667 | Q11: 8632.1968 | R11: Q4
A12: Base | B12: 11 | C12: 45962 | D12: 1 | E12: 0 | F12: 51.246911 | G12: 42705.759 | H12: 12.249484 | I12: 10207.903 | J12: 8166.3228 | K12: -508.72082 | L12: 40155.458 | M12: -3333.3333 | N12: -2048.6111 | O12: 34773.513 | P12: -26041.667 | Q12: 8731.8464 | R12: Q4
A13: Base | B13: 12 | C13: 45992 | D13: 1 | E13: 0 | F13: 51.3733 | G13: 42811.083 | H13: 12.274716 | I13: 10228.93 | J13: 8183.1441 | K13: -509.94227 | L13: 40255.355 | M13: -3333.3333 | N13: -2048.6111 | O13: 34873.41 | P13: -26041.667 | Q13: 8831.7436 | R13: Q4
B14: Totals | F14: =SUM(F2:F13) -> 608.20597 | G14: =SUM(G2:G13) -> 423402.21 | I14: =SUM(I2:I13) -> 121368.87 | J14: =SUM(J2:J13) -> 89095.096 | K14: =SUM(K2:K13) -> -5124.9731 | L14: =SUM(L2:L13) -> 386003.47 | M14: =SUM(M2:M13) -> -40000 | N14: =SUM(N2:N13) -> -24583.333 | O14: =SUM(O2:O13) -> 321420.13 | P14: =SUM(P2:P13) -> -312500 | Q14: =SUM(Q2:Q13) -> 8920.1337
A16: Scenario Selection | B16: Month_Index | C16: Month_Start | D16: Occupied | E16: FreeRent | F16: Rent_psf_pa | G16: Base_Rent | H16: Expense_psf_pa | I16: OpEx | J16: Recoveries | K16: Bad_Debt | L16: NOI_pre_Amort | M16: TI_Amort | N16: LC_Amort | O16: NOI | P16: Interest_Expense | Q16: AFFO | R16: Quarter
A17: Upside | B17: 1 | C17: 45658 | D17: 0 | E17: 0 | F17: 50 | G17: 0 | H17: 12 | I17: 10000 | J17: 0 | K17: 0 | L17: -10000 | M17: -3333.3333 | N17: -2048.6111 | O17: -15381.944 | P17: -26041.667 | Q17: -41423.611 | R17: Q1
A18: Upside | B18: 2 | C18: 45689 | D18: 1 | E18: 1 | F18: 50.203706 | G18: 0 | H18: 12.014898 | I18: 10012.415 | J18: 9011.1734 | K18: -45.055867 | L18: -1046.2974 | M18: -3333.3333 | N18: -2048.6111 | O18: -6428.2418 | P18: -26041.667 | Q18: -32469.908 | R18: Q1
A19: Upside | B19: 3 | C19: 45717 | D19: 1 | E19: 0 | F19: 50.408242 | G19: 42006.869 | H19: 12.029814 | I19: 10024.845 | J19: 9022.3607 | K19: -255.14615 | L19: 40749.238 | M19: -3333.3333 | N19: -2048.6111 | O19: 35367.293 | P19: -26041.667 | Q19: 9325.6268 | R19: Q1
A20: Upside | B20: 4 | C20: 45748 | D20: 1 | E20: 0 | F20: 50.613612 | G20: 42178.01 | H20: 12.044749 | I20: 10037.291 | J20: 9033.5618 | K20: -256.05786 | L20: 40918.223 | M20: -3333.3333 | N20: -2048.6111 | O20: 35536.278 | P20: -26041.667 | Q20: 9494.6117 | R20: Q2
A21: Upside | B21: 5 | C21: 45778 | D21: 1 | E21: 0 | F21: 50.819818 | G21: 42349.848 | H21: 12.059702 | I21: 10049.752 | J21: 9044.7769 | K21: -256.97313 | L21: 41087.9 | M21: -3333.3333 | N21: -2048.6111 | O21: 35705.955 | P21: -26041.667 | Q21: 9664.2888 | R21: Q2
A22: Upside | B22: 6 | C22: 45809 | D22: 1 | E22: 0 | F22: 51.026864 | G22: 42522.387 | H22: 12.074674 | I22: 10062.229 | J22: 9056.0058 | K22: -257.89196 | L22: 41258.272 | M22: -3333.3333 | N22: -2048.6111 | O22: 35876.327 | P22: -26041.667 | Q22: 9834.6608 | R22: Q2
A23: Upside | B23: 7 | C23: 45839 | D23: 1 | E23: 0 | F23: 51.234754 | G23: 42695.628 | H23: 12.089665 | I23: 10074.721 | J23: 9067.2488 | K23: -258.81438 | L23: 41429.342 | M23: -3333.3333 | N23: -2048.6111 | O23: 36047.397 | P23: -26041.667 | Q23: 10005.731 | R23: Q3
A24: Upside | B24: 8 | C24: 45870 | D24: 1 | E24: 0 | F24: 51.443491 | G24: 42869.575 | H24: 12.104674 | I24: 10087.228 | J24: 9078.5056 | K24: -259.74041 | L24: 41601.112 | M24: -3333.3333 | N24: -2048.6111 | O24: 36219.168 | P24: -26041.667 | Q24: 10177.501 | R24: Q3
A25: Upside | B25: 9 | C25: 45901 | D25: 1 | E25: 0 | F25: 51.653078 | G25: 43044.231 | H25: 12.119702 | I25: 10099.752 | J25: 9089.7765 | K25: -260.67004 | L25: 41773.586 | M25: -3333.3333 | N25: -2048.6111 | O25: 36391.642 | P25: -26041.667 | Q25: 10349.975 | R25: Q3
A26: Upside | B26: 10 | C26: 45931 | D26: 1 | E26: 0 | F26: 51.863519 | G26: 43219.599 | H26: 12.134748 | I26: 10112.29 | J26: 9101.0613 | K26: -261.6033 | L26: 41946.767 | M26: -3333.3333 | N26: -2048.6111 | O26: 36564.822 | P26: -26041.667 | Q26: 10523.156 | R26: Q4
A27: Upside | B27: 11 | C27: 45962 | D27: 1 | E27: 0 | F27: 52.074817 | G27: 43395.681 | H27: 12.149814 | I27: 10124.845 | J27: 9112.3602 | K27: -262.54021 | L27: 42120.656 | M27: -3333.3333 | N27: -2048.6111 | O27: 36738.712 | P27: -26041.667 | Q27: 10697.045 | R27: Q4
A28: Upside | B28: 12 | C28: 45992 | D28: 1 | E28: 0 | F28: 52.286976 | G28: 43572.48 | H28: 12.164897 | I28: 10137.415 | J28: 9123.6731 | K28: -263.48077 | L28: 42295.258 | M28: -3333.3333 | N28: -2048.6111 | O28: 36913.314 | P28: -26041.667 | Q28: 10871.647 | R28: Q4
B29: Totals | F29: =SUM(F17:F28) -> 613.62888 | G29: =SUM(G17:G28) -> 427854.31 | I29: =SUM(I17:I28) -> 120822.78 | J29: =SUM(J17:J28) -> 99740.504 | K29: =SUM(K17:K28) -> -2637.9741 | L29: =SUM(L17:L28) -> 404134.06 | M29: =SUM(M17:M28) -> -40000 | N29: =SUM(N17:N28) -> -24583.333 | O29: =SUM(O17:O28) -> 339550.72 | P29: =SUM(P17:P28) -> -312500 | Q29: =SUM(Q17:Q28) -> 27050.723
A31: Scenario Selection | B31: Month_Index | C31: Month_Start | D31: Occupied | E31: FreeRent | F31: Rent_psf_pa | G31: Base_Rent | H31: Expense_psf_pa | I31: OpEx | J31: Recoveries | K31: Bad_Debt | L31: NOI_pre_Amort | M31: TI_Amort | N31: LC_Amort | O31: NOI | P31: Interest_Expense | Q31: AFFO | R31: Quarter
A32: Downside | B32: 1 | C32: 45658 | D32: 0 | E32: 0 | F32: 50 | G32: 0 | H32: 12 | I32: 10000 | J32: 0 | K32: 0 | L32: -10000 | M32: -3333.3333 | N32: -2048.6111 | O32: -15381.944 | P32: -28125 | Q32: -43506.944 | R32: Q1
A33: Downside | B33: 2 | C33: 45689 | D33: 0 | E33: 0 | F33: 50 | G33: 0 | H33: 12.034451 | I33: 10028.709 | J33: 0 | K33: 0 | L33: -10028.709 | M33: -3333.3333 | N33: -2048.6111 | O33: -15410.653 | P33: -28125 | Q33: -43535.653 | R33: Q1
A34: Downside | B34: 3 | C34: 45717 | D34: 1 | E34: 1 | F34: 50 | G34: 0 | H34: 12.069 | I34: 10057.5 | J34: 7040.2503 | K34: -140.80501 | L34: -3158.0551 | M34: -3333.3333 | N34: -2048.6111 | O34: -8539.9996 | P34: -28125 | Q34: -36665 | R34: Q1
A35: Downside | B35: 4 | C35: 45748 | D35: 1 | E35: 0 | F35: 50 | G35: 41666.667 | H35: 12.103649 | I35: 10086.374 | J35: 7060.4621 | K35: -974.54258 | L35: 37666.212 | M35: -3333.3333 | N35: -2048.6111 | O35: 32284.267 | P35: -28125 | Q35: 4159.2673 | R35: Q2
A36: Downside | B36: 5 | C36: 45778 | D36: 1 | E36: 0 | F36: 50 | G36: 41666.667 | H36: 12.138398 | I36: 10115.331 | J36: 7080.732 | K36: -974.94797 | L36: 37657.119 | M36: -3333.3333 | N36: -2048.6111 | O36: 32275.175 | P36: -28125 | Q36: 4150.1748 | R36: Q2
A37: Downside | B37: 6 | C37: 45809 | D37: 1 | E37: 0 | F37: 50 | G37: 41666.667 | H37: 12.173246 | I37: 10144.372 | J37: 7101.0601 | K37: -975.35453 | L37: 37648.001 | M37: -3333.3333 | N37: -2048.6111 | O37: 32266.056 | P37: -28125 | Q37: 4141.0562 | R37: Q2
A38: Downside | B38: 7 | C38: 45839 | D38: 1 | E38: 0 | F38: 50 | G38: 41666.667 | H38: 12.208194 | I38: 10173.495 | J38: 7121.4465 | K38: -975.76226 | L38: 37638.856 | M38: -3333.3333 | N38: -2048.6111 | O38: 32256.911 | P38: -28125 | Q38: 4131.9115 | R38: Q3
A39: Downside | B39: 8 | C39: 45870 | D39: 1 | E39: 0 | F39: 50 | G39: 41666.667 | H39: 12.243242 | I39: 10202.702 | J39: 7141.8914 | K39: -976.17116 | L39: 37629.685 | M39: -3333.3333 | N39: -2048.6111 | O39: 32247.74 | P39: -28125 | Q39: 4122.7404 | R39: Q3
A40: Downside | B40: 9 | C40: 45901 | D40: 1 | E40: 0 | F40: 50 | G40: 41666.667 | H40: 12.278392 | I40: 10231.993 | J40: 7162.3951 | K40: -976.58123 | L40: 37620.488 | M40: -3333.3333 | N40: -2048.6111 | O40: 32238.543 | P40: -28125 | Q40: 4113.5431 | R40: Q3
A41: Downside | B41: 10 | C41: 45931 | D41: 1 | E41: 0 | F41: 50 | G41: 41666.667 | H41: 12.313642 | I41: 10261.368 | J41: 7182.9576 | K41: -976.99249 | L41: 37611.264 | M41: -3333.3333 | N41: -2048.6111 | O41: 32229.319 | P41: -28125 | Q41: 4104.3193 | R41: Q4
A42: Downside | B42: 11 | C42: 45962 | D42: 1 | E42: 0 | F42: 50 | G42: 41666.667 | H42: 12.348993 | I42: 10290.827 | J42: 7203.5791 | K42: -977.40492 | L42: 37602.014 | M42: -3333.3333 | N42: -2048.6111 | O42: 32220.069 | P42: -28125 | Q42: 4095.0691 | R42: Q4
...

Sheet Summary
A1: Scenario Selection | B1: Month_Index | C1: Month_Start | D1: Occupied | E1: FreeRent | F1: Rent_psf_pa | G1: Base_Rent | H1: Expense_psf_pa | I1: OpEx | J1: Recoveries | K1: Bad_Debt | L1: NOI_pre_Amort | M1: TI_Amort | N1: LC_Amort | O1: NOI | P1: Interest_Expense | Q1: AFFO | R1: Δ vs Base (NOI_pre_Amort) | S1: Δ % (NOI_pre_Amort)
A2: =Inputs!$A$3 -> Base | B2: =Timeline!A2 -> 1 | C2: =Timeline!B2 -> 45658 | D2: =IF(AND(B2>=Inputs!$I$3+1,B2<=Inputs!$I$3+Inputs!$H$3),1,0) -> 0 | E2: =IF(AND(B2>=Inputs!$I$3+1,B2<=Inputs!$I$3+Inputs!$G$3),1,0) -> 0 | F2: =Inputs!$E$3*POWER(1+Inputs!$F$3, (B2-1)/12) -> 50 | G2: =D2*(1-E2)*(F2/12)*Inputs!$D$3 -> 0 | H2: =Inputs!$J$3*POWER(1+Inputs!$K$3, (B2-1)/12) -> 12 | I2: =(H2/12)*Inputs!$D$3 -> 10000 | J2: =D2*Inputs!$L$3*I2 -> 0 | K2: =-(G2+J2)*Inputs!$M$3 -> 0 | L2: =G2+J2+K2-I2 -> -10000 | M2: =IF(B2<=Inputs!$P$3*12,-(Inputs!$N$3*Inputs!$D$3)/(Inputs!$P$3*12),0) -> -3333.3333 | N2: =IF(B2<=Inputs!$Q$3*12,-(Inputs!$O$3*(Inputs!$E$3/12)*Inputs!$D$3*(Inputs!$H$3-Inputs!$G$3))/(Inputs!$Q$3*12),0) -> -2048.6111 | O2: =L2+M2+N2 -> -15381.944 | P2: =-( Inputs!$R$3*( Inputs!$U$3*Inputs!$V$3 + (1-Inputs!$U$3)*(Inputs!$S$3+Inputs!$T$3) ) )/12 -> -26041.667 | Q2: =O2+P2 -> -41423.611
A3: =Inputs!$A$3 -> Base | B3: =Timeline!A3 -> 2 | C3: =Timeline!B3 -> 45689 | D3: =IF(AND(B3>=Inputs!$I$3+1,B3<=Inputs!$I$3+Inputs!$H$3),1,0) -> 1 | E3: =IF(AND(B3>=Inputs!$I$3+1,B3<=Inputs!$I$3+Inputs!$G$3),1,0) -> 1 | F3: =Inputs!$E$3*POWER(1+Inputs!$F$3, (B3-1)/12) -> 50.123313 | G3: =D3*(1-E3)*(F3/12)*Inputs!$D$3 -> 0 | H3: =Inputs!$J$3*POWER(1+Inputs!$K$3, (B3-1)/12) -> 12.024718 | I3: =(H3/12)*Inputs!$D$3 -> 10020.598 | J3: =D3*Inputs!$L$3*I3 -> 8016.4787 | K3: =-(G3+J3)*Inputs!$M$3 -> -80.164787 | L3: =G3+J3+K3-I3 -> -2084.2845 | M3: =IF(B3<=Inputs!$P$3*12,-(Inputs!$N$3*Inputs!$D$3)/(Inputs!$P$3*12),0) -> -3333.3333 | N3: =IF(B3<=Inputs!$Q$3*12,-(Inputs!$O$3*(Inputs!$E$3/12)*Inputs!$D$3*(Inputs!$H$3-Inputs!$G$3))/(Inputs!$Q$3*12),0) -> -2048.6111 | O3: =L3+M3+N3 -> -7466.2289 | P3: =-( Inputs!$R$3*( Inputs!$U$3*Inputs!$V$3 + (1-Inputs!$U$3)*(Inputs!$S$3+Inputs!$T$3) ) )/12 -> -26041.667 | Q3: =O3+P3 -> -33507.896
A4: =Inputs!$A$3 -> Base | B4: =Timeline!A4 -> 3 | C4: =Timeline!B4 -> 45717 | D4: =IF(AND(B4>=Inputs!$I$3+1,B4<=Inputs!$I$3+Inputs!$H$3),1,0) -> 1 | E4: =IF(AND(B4>=Inputs!$I$3+1,B4<=Inputs!$I$3+Inputs!$G$3),1,0) -> 0 | F4: =Inputs!$E$3*POWER(1+Inputs!$F$3, (B4-1)/12) -> 50.246931 | G4: =D4*(1-E4)*(F4/12)*Inputs!$D$3 -> 41872.443 | H4: =Inputs!$J$3*POWER(1+Inputs!$K$3, (B4-1)/12) -> 12.049487 | I4: =(H4/12)*Inputs!$D$3 -> 10041.239 | J4: =D4*Inputs!$L$3*I4 -> 8032.9913 | K4: =-(G4+J4)*Inputs!$M$3 -> -499.05434 | L4: =G4+J4+K4-I4 -> 39365.14 | M4: =IF(B4<=Inputs!$P$3*12,-(Inputs!$N$3*Inputs!$D$3)/(Inputs!$P$3*12),0) -> -3333.3333 | N4: =IF(B4<=Inputs!$Q$3*12,-(Inputs!$O$3*(Inputs!$E$3/12)*Inputs!$D$3*(Inputs!$H$3-Inputs!$G$3))/(Inputs!$Q$3*12),0) -> -2048.6111 | O4: =L4+M4+N4 -> 33983.196 | P4: =-( Inputs!$R$3*( Inputs!$U$3*Inputs!$V$3 + (1-Inputs!$U$3)*(Inputs!$S$3+Inputs!$T$3) ) )/12 -> -26041.667 | Q4: =O4+P4 -> 7941.5293
A5: =Inputs!$A$3 -> Base | B5: =Timeline!A5 -> 4 | C5: =Timeline!B5 -> 45748 | D5: =IF(AND(B5>=Inputs!$I$3+1,B5<=Inputs!$I$3+Inputs!$H$3),1,0) -> 1 | E5: =IF(AND(B5>=Inputs!$I$3+1,B5<=Inputs!$I$3+Inputs!$G$3),1,0) -> 0 | F5: =Inputs!$E$3*POWER(1+Inputs!$F$3, (B5-1)/12) -> 50.370854 | G5: =D5*(1-E5)*(F5/12)*Inputs!$D$3 -> 41975.711 | H5: =Inputs!$J$3*POWER(1+Inputs!$K$3, (B5-1)/12) -> 12.074307 | I5: =(H5/12)*Inputs!$D$3 -> 10061.922 | J5: =D5*Inputs!$L$3*I5 -> 8049.538 | K5: =-(G5+J5)*Inputs!$M$3 -> -500.25249 | L5: =G5+J5+K5-I5 -> 39463.074 | M5: =IF(B5<=Inputs!$P$3*12,-(Inputs!$N$3*Inputs!$D$3)/(Inputs!$P$3*12),0) -> -3333.3333 | N5: =IF(B5<=Inputs!$Q$3*12,-(Inputs!$O$3*(Inputs!$E$3/12)*Inputs!$D$3*(Inputs!$H$3-Inputs!$G$3))/(Inputs!$Q$3*12),0) -> -2048.6111 | O5: =L5+M5+N5 -> 34081.13 | P5: =-( Inputs!$R$3*( Inputs!$U$3*Inputs!$V$3 + (1-Inputs!$U$3)*(Inputs!$S$3+Inputs!$T$3) ) )/12 -> -26041.667 | Q5: =O5+P5 -> 8039.4632
A6: =Inputs!$A$3 -> Base | B6: =Timeline!A6 -> 5 | C6: =Timeline!B6 -> 45778 | D6: =IF(AND(B6>=Inputs!$I$3+1,B6<=Inputs!$I$3+Inputs!$H$3),1,0) -> 1 | E6: =IF(AND(B6>=Inputs!$I$3+1,B6<=Inputs!$I$3+Inputs!$G$3),1,0) -> 0 | F6: =Inputs!$E$3*POWER(1+Inputs!$F$3, (B6-1)/12) -> 50.495082 | G6: =D6*(1-E6)*(F6/12)*Inputs!$D$3 -> 42079.235 | H6: =Inputs!$J$3*POWER(1+Inputs!$K$3, (B6-1)/12) -> 12.099178 | I6: =(H6/12)*Inputs!$D$3 -> 10082.648 | J6: =D6*Inputs!$L$3*I6 -> 8066.1187 | K6: =-(G6+J6)*Inputs!$M$3 -> -501.45353 | L6: =G6+J6+K6-I6 -> 39561.252 | M6: =IF(B6<=Inputs!$P$3*12,-(Inputs!$N$3*Inputs!$D$3)/(Inputs!$P$3*12),0) -> -3333.3333 | N6: =IF(B6<=Inputs!$Q$3*12,-(Inputs!$O$3*(Inputs!$E$3/12)*Inputs!$D$3*(Inputs!$H$3-Inputs!$G$3))/(Inputs!$Q$3*12),0) -> -2048.6111 | O6: =L6+M6+N6 -> 34179.307 | P6: =-( Inputs!$R$3*( Inputs!$U$3*Inputs!$V$3 + (1-Inputs!$U$3)*(Inputs!$S$3+Inputs!$T$3) ) )/12 -> -26041.667 | Q6: =O6+P6 -> 8137.6404
A7: =Inputs!$A$3 -> Base | B7: =Timeline!A7 -> 6 | C7: =Timeline!B7 -> 45809 | D7: =IF(AND(B7>=Inputs!$I$3+1,B7<=Inputs!$I$3+Inputs!$H$3),1,0) -> 1 | E7: =IF(AND(B7>=Inputs!$I$3+1,B7<=Inputs!$I$3+Inputs!$G$3),1,0) -> 0 | F7: =Inputs!$E$3*POWER(1+Inputs!$F$3, (B7-1)/12) -> 50.619616 | G7: =D7*(1-E7)*(F7/12)*Inputs!$D$3 -> 42183.013 | H7: =Inputs!$J$3*POWER(1+Inputs!$K$3, (B7-1)/12) -> 12.1241 | I7: =(H7/12)*Inputs!$D$3 -> 10103.417 | J7: =D7*Inputs!$L$3*I7 -> 8082.7336 | K7: =-(G7+J7)*Inputs!$M$3 -> -502.65747 | L7: =G7+J7+K7-I7 -> 39659.673 | M7: =IF(B7<=Inputs!$P$3*12,-(Inputs!$N$3*Inputs!$D$3)/(Inputs!$P$3*12),0) -> -3333.3333 | N7: =IF(B7<=Inputs!$Q$3*12,-(Inputs!$O$3*(Inputs!$E$3/12)*Inputs!$D$3*(Inputs!$H$3-Inputs!$G$3))/(Inputs!$Q$3*12),0) -> -2048.6111 | O7: =L7+M7+N7 -> 34277.728 | P7: =-( Inputs!$R$3*( Inputs!$U$3*Inputs!$V$3 + (1-Inputs!$U$3)*(Inputs!$S$3+Inputs!$T$3) ) )/12 -> -26041.667 | Q7: =O7+P7 -> 8236.0615
A8: =Inputs!$A$3 -> Base | B8: =Timeline!A8 -> 7 | C8: =Timeline!B8 -> 45839 | D8: =IF(AND(B8>=Inputs!$I$3+1,B8<=Inputs!$I$3+Inputs!$H$3),1,0) -> 1 | E8: =IF(AND(B8>=Inputs!$I$3+1,B8<=Inputs!$I$3+Inputs!$G$3),1,0) -> 0 | F8: =Inputs!$E$3*POWER(1+Inputs!$F$3, (B8-1)/12) -> 50.744458 | G8: =D8*(1-E8)*(F8/12)*Inputs!$D$3 -> 42287.048 | H8: =Inputs!$J$3*POWER(1+Inputs!$K$3, (B8-1)/12) -> 12.149074 | I8: =(H8/12)*Inputs!$D$3 -> 10124.228 | J8: =D8*Inputs!$L$3*I8 -> 8099.3827 | K8: =-(G8+J8)*Inputs!$M$3 -> -503.86431 | L8: =G8+J8+K8-I8 -> 39758.338 | M8: =IF(B8<=Inputs!$P$3*12,-(Inputs!$N$3*Inputs!$D$3)/(Inputs!$P$3*12),0) -> -3333.3333 | N8: =IF(B8<=Inputs!$Q$3*12,-(Inputs!$O$3*(Inputs!$E$3/12)*Inputs!$D$3*(Inputs!$H$3-Inputs!$G$3))/(Inputs!$Q$3*12),0) -> -2048.6111 | O8: =L8+M8+N8 -> 34376.394 | P8: =-( Inputs!$R$3*( Inputs!$U$3*Inputs!$V$3 + (1-Inputs!$U$3)*(Inputs!$S$3+Inputs!$T$3) ) )/12 -> -26041.667 | Q8: =O8+P8 -> 8334.7271
A9: =Inputs!$A$3 -> Base | B9: =Timeline!A9 -> 8 | C9: =Timeline!B9 -> 45870 | D9: =IF(AND(B9>=Inputs!$I$3+1,B9<=Inputs!$I$3+Inputs!$H$3),1,0) -> 1 | E9: =IF(AND(B9>=Inputs!$I$3+1,B9<=Inputs!$I$3+Inputs!$G$3),1,0) -> 0 | F9: =Inputs!$E$3*POWER(1+Inputs!$F$3, (B9-1)/12) -> 50.869607 | G9: =D9*(1-E9)*(F9/12)*Inputs!$D$3 -> 42391.339 | H9: =Inputs!$J$3*POWER(1+Inputs!$K$3, (B9-1)/12) -> 12.174099 | I9: =(H9/12)*Inputs!$D$3 -> 10145.083 | J9: =D9*Inputs!$L$3*I9 -> 8116.0661 | K9: =-(G9+J9)*Inputs!$M$3 -> -505.07406 | L9: =G9+J9+K9-I9 -> 39857.249 | M9: =IF(B9<=Inputs!$P$3*12,-(Inputs!$N$3*Inputs!$D$3)/(Inputs!$P$3*12),0) -> -3333.3333 | N9: =IF(B9<=Inputs!$Q$3*12,-(Inputs!$O$3*(Inputs!$E$3/12)*Inputs!$D$3*(Inputs!$H$3-Inputs!$G$3))/(Inputs!$Q$3*12),0) -> -2048.6111 | O9: =L9+M9+N9 -> 34475.304 | P9: =-( Inputs!$R$3*( Inputs!$U$3*Inputs!$V$3 + (1-Inputs!$U$3)*(Inputs!$S$3+Inputs!$T$3) ) )/12 -> -26041.667 | Q9: =O9+P9 -> 8433.6378
A10: =Inputs!$A$3 -> Base | B10: =Timeline!A10 -> 9 | C10: =Timeline!B10 -> 45901 | D10: =IF(AND(B10>=Inputs!$I$3+1,B10<=Inputs!$I$3+Inputs!$H$3),1,0) -> 1 | E10: =IF(AND(B10>=Inputs!$I$3+1,B10<=Inputs!$I$3+Inputs!$G$3),1,0) -> 0 | F10: =Inputs!$E$3*POWER(1+Inputs!$F$3, (B10-1)/12) -> 50.995066 | G10: =D10*(1-E10)*(F10/12)*Inputs!$D$3 -> 42495.888 | H10: =Inputs!$J$3*POWER(1+Inputs!$K$3, (B10-1)/12) -> 12.199176 | I10: =(H10/12)*Inputs!$D$3 -> 10165.98 | J10: =D10*Inputs!$L$3*I10 -> 8132.7839 | K10: =-(G10+J10)*Inputs!$M$3 -> -506.28672 | L10: =G10+J10+K10-I10 -> 39956.405 | M10: =IF(B10<=Inputs!$P$3*12,-(Inputs!$N$3*Inputs!$D$3)/(Inputs!$P$3*12),0) -> -3333.3333 | N10: =IF(B10<=Inputs!$Q$3*12,-(Inputs!$O$3*(Inputs!$E$3/12)*Inputs!$D$3*(Inputs!$H$3-Inputs!$G$3))/(Inputs!$Q$3*12),0) -> -2048.6111 | O10: =L10+M10+N10 -> 34574.461 | P10: =-( Inputs!$R$3*( Inputs!$U$3*Inputs!$V$3 + (1-Inputs!$U$3)*(Inputs!$S$3+Inputs!$T$3) ) )/12 -> -26041.667 | Q10: =O10+P10 -> 8532.7941
A11: =Inputs!$A$3 -> Base | B11: =Timeline!A11 -> 10 | C11: =Timeline!B11 -> 45931 | D11: =IF(AND(B11>=Inputs!$I$3+1,B11<=Inputs!$I$3+Inputs!$H$3),1,0) -> 1 | E11: =IF(AND(B11>=Inputs!$I$3+1,B11<=Inputs!$I$3+Inputs!$G$3),1,0) -> 0 | F11: =Inputs!$E$3*POWER(1+Inputs!$F$3, (B11-1)/12) -> 51.120833 | G11: =D11*(1-E11)*(F11/12)*Inputs!$D$3 -> 42600.694 | H11: =Inputs!$J$3*POWER(1+Inputs!$K$3, (B11-1)/12) -> 12.224304 | I11: =(H11/12)*Inputs!$D$3 -> 10186.92 | J11: =D11*Inputs!$L$3*I11 -> 8149.5361 | K11: =-(G11+J11)*Inputs!$M$3 -> -507.5023 | L11: =G11+J11+K11-I11 -> 40055.808 | M11: =IF(B11<=Inputs!$P$3*12,-(Inputs!$N$3*Inputs!$D$3)/(Inputs!$P$3*12),0) -> -3333.3333 | N11: =IF(B11<=Inputs!$Q$3*12,-(Inputs!$O$3*(Inputs!$E$3/12)*Inputs!$D$3*(Inputs!$H$3-Inputs!$G$3))/(Inputs!$Q$3*12),0) -> -2048.6111 | O11: =L11+M11+N11 -> 34673.863 | P11: =-( Inputs!$R$3*( Inputs!$U$3*Inputs!$V$3 + (1-Inputs!$U$3)*(Inputs!$S$3+Inputs!$T$3) ) )/12 -> -26041.667 | Q11: =O11+P11 -> 8632.1968
A12: =Inputs!$A$3 -> Base | B12: =Timeline!A12 -> 11 | C12: =Timeline!B12 -> 45962 | D12: =IF(AND(B12>=Inputs!$I$3+1,B12<=Inputs!$I$3+Inputs!$H$3),1,0) -> 1 | E12: =IF(AND(B12>=Inputs!$I$3+1,B12<=Inputs!$I$3+Inputs!$G$3),1,0) -> 0 | F12: =Inputs!$E$3*POWER(1+Inputs!$F$3, (B12-1)/12) -> 51.246911 | G12: =D12*(1-E12)*(F12/12)*Inputs!$D$3 -> 42705.759 | H12: =Inputs!$J$3*POWER(1+Inputs!$K$3, (B12-1)/12) -> 12.249484 | I12: =(H12/12)*Inputs!$D$3 -> 10207.903 | J12: =D12*Inputs!$L$3*I12 -> 8166.3228 | K12: =-(G12+J12)*Inputs!$M$3 -> -508.72082 | L12: =G12+J12+K12-I12 -> 40155.458 | M12: =IF(B12<=Inputs!$P$3*12,-(Inputs!$N$3*Inputs!$D$3)/(Inputs!$P$3*12),0) -> -3333.3333 | N12: =IF(B12<=Inputs!$Q$3*12,-(Inputs!$O$3*(Inputs!$E$3/12)*Inputs!$D$3*(Inputs!$H$3-Inputs!$G$3))/(Inputs!$Q$3*12),0) -> -2048.6111 | O12: =L12+M12+N12 -> 34773.513 | P12: =-( Inputs!$R$3*( Inputs!$U$3*Inputs!$V$3 + (1-Inputs!$U$3)*(Inputs!$S$3+Inputs!$T$3) ) )/12 -> -26041.667 | Q12: =O12+P12 -> 8731.8464
A13: =Inputs!$A$3 -> Base | B13: =Timeline!A13 -> 12 | C13: =Timeline!B13 -> 45992 | D13: =IF(AND(B13>=Inputs!$I$3+1,B13<=Inputs!$I$3+Inputs!$H$3),1,0) -> 1 | E13: =IF(AND(B13>=Inputs!$I$3+1,B13<=Inputs!$I$3+Inputs!$G$3),1,0) -> 0 | F13: =Inputs!$E$3*POWER(1+Inputs!$F$3, (B13-1)/12) -> 51.3733 | G13: =D13*(1-E13)*(F13/12)*Inputs!$D$3 -> 42811.083 | H13: =Inputs!$J$3*POWER(1+Inputs!$K$3, (B13-1)/12) -> 12.274716 | I13: =(H13/12)*Inputs!$D$3 -> 10228.93 | J13: =D13*Inputs!$L$3*I13 -> 8183.1441 | K13: =-(G13+J13)*Inputs!$M$3 -> -509.94227 | L13: =G13+J13+K13-I13 -> 40255.355 | M13: =IF(B13<=Inputs!$P$3*12,-(Inputs!$N$3*Inputs!$D$3)/(Inputs!$P$3*12),0) -> -3333.3333 | N13: =IF(B13<=Inputs!$Q$3*12,-(Inputs!$O$3*(Inputs!$E$3/12)*Inputs!$D$3*(Inputs!$H$3-Inputs!$G$3))/(Inputs!$Q$3*12),0) -> -2048.6111 | O13: =L13+M13+N13 -> 34873.41 | P13: =-( Inputs!$R$3*( Inputs!$U$3*Inputs!$V$3 + (1-Inputs!$U$3)*(Inputs!$S$3+Inputs!$T$3) ) )/12 -> -26041.667 | Q13: =O13+P13 -> 8831.7436
B14: Totals | F14: =SUM(F2:F13) -> 608.20597 | G14: =SUM(G2:G13) -> 423402.21 | I14: =SUM(I2:I13) -> 121368.87 | J14: =SUM(J2:J13) -> 89095.096 | K14: =SUM(K2:K13) -> -5124.9731 | L14: =SUM(L2:L13) -> 386003.47 | M14: =SUM(M2:M13) -> -40000 | N14: =SUM(N2:N13) -> -24583.333 | O14: =SUM(O2:O13) -> 321420.13 | P14: =SUM(P2:P13) -> -312500 | Q14: =SUM(Q2:Q13) -> 8920.1337
L16: YEAR | Q16: YEAR | U16: Q1
D17: Downtime_Months | G17: Annual_Rent_Growth_pct | H17: Expense_Growth_pct | J17: CAM_Recovery_pct | K17: Bad_Debt_pct_of_Rent | L17: NOI_pre_Amort | M17: Δ vs Base (NOI_pre_Amort) | N17: Δ % (NOI_pre_Amort) | O17: NOI | P17: Reference_Rate_pct | Q17: AFFO | R17: Δ vs Base (AFFO) | S17: Δ % (AFFO) | U17: NOI_pre_Amort | V17: Δ vs Base (NOI_pre_Amort) | W17: Δ % (NOI_pre_Amort) | X17: AFFO | Y17: Δ vs Base (AFFO) | Z17: Δ % (AFFO)
C18: Base | D18: 1 | G18: 0.03 | H18: 0.025 | J18: 0.8 | K18: 0.01 | L18: =N30 -> 386003.47 | O18: =Q30 -> 321420.13 | P18: 0.05 | Q18: =S30 -> 8920.1337 | U18: =N26 -> 27280.856 | X18: =S26 -> -66989.977
C19: Upside | D19: 1 | G19: 0.05 | H19: 0.015 | J19: 0.9 | K19: 0.005 | L19: =N35 -> 404134.06 | M19: =L19-$L$18 -> 18130.589 | N19: =L19/$L$18-1 -> 0.046970017 | O19: =Q35 -> 339550.72 | P19: 0.05 | Q19: =S35 -> 27050.723 | R19: =Q19-$Q$18 -> 18130.589 | S19: =Q19/$Q$18-1 -> 2.0325468 | U19: =N31 -> 29702.941 | V19: =U19-$U$18 -> 2422.0846 | W19: =U19/$U$18-1 -> 0.088783307 | X19: =S31 -> -64567.893 | Y19: =X19-$X$18 -> 2422.0846 | Z19: =X19/$X$18-1 -> -0.036155925
C20: Downside | D20: 2 | G20: 0 | H20: 0.035 | J20: 0.7 | K20: 0.02 | L20: =N40 -> 315479.61 | M20: =L20-$L$18 -> -70523.857 | N20: =L20/$L$18-1 -> -0.18270265 | O20: =Q40 -> 250896.28 | P20: 0.06 | Q20: =S40 -> -86603.723 | R20: =Q20-$Q$18 -> -95523.857 | S20: =Q20/$Q$18-1 -> -10.708792 | U20: =N36 -> -23186.764 | V20: =U20-$U$18 -> -50467.62 | W20: =U20/$U$18-1 -> -1.849928 | X20: =S36 -> -123707.6 | Y20: =X20-$X$18 -> -56717.62 | Z20: =X20/$X$18-1 -> 0.8466583
F25: Occupied_ | G25: FreeRent_ | H25: Rent_psf_pa_ | I25: Base_Rent_ | J25: Expense_psf_pa_ | K25: OpEx_ | L25: Recoveries_ | M25: Bad_Debt_ | N25: NOI_pre_Amort_ | O25: TI_Amort_ | P25: LC_Amort_ | Q25: NOI_ | R25: Interest_Expense_ | S25: AFFO_
C26: Base | D26: Q1 | F26: 2 | G26: 1 | H26: 150.37024 | I26: 41872.443 | J26: 36.074205 | K26: 30061.838 | L26: 16049.47 | M26: -579.21913 | N26: 27280.856 | O26: -10000 | P26: -6145.8333 | Q26: 11135.023 | R26: -78125 | S26: -66989.977
D27: Q2 | F27: 3 | G27: 0 | H27: 151.48555 | I27: 126237.96 | J27: 36.297585 | K27: 30247.988 | L27: 24198.39 | M27: -1504.3635 | N27: 118684 | O27: -10000 | P27: -6145.8333 | Q27: 102538.17 | R27: -78125 | S27: 24413.165
D28: Q3 | F28: 3 | G28: 0 | H28: 152.60913 | I28: 127174.28 | J28: 36.522349 | K28: 30435.291 | L28: 24348.233 | M28: -1515.2251 | N28: 119571.99 | O28: -10000 | P28: -6145.8333 | Q28: 103426.16 | R28: -78125 | S28: 25301.159
D29: Q4 | F29: 3 | G29: 0 | H29: 153.74104 | I29: 128117.54 | J29: 36.748504 | K29: 30623.754 | L29: 24499.003 | M29: -1526.1654 | N29: 120466.62 | O29: -10000 | P29: -6145.8333 | Q29: 104320.79 | R29: -78125 | S29: 26195.787
C30: Base Total | F30: 11 | G30: 1 | H30: 608.20597 | I30: 423402.21 | J30: 145.64264 | K30: 121368.87 | L30: 89095.096 | M30: -5124.9731 | N30: 386003.47 | O30: -40000 | P30: -24583.333 | Q30: 321420.13 | R30: -312500 | S30: 8920.1337
C31: Upside | D31: Q1 | F31: 2 | G31: 1 | H31: 150.61195 | I31: 42006.869 | J31: 36.044712 | K31: 30037.26 | L31: 18033.534 | M31: -300.20201 | N31: 29702.941 | O31: -10000 | P31: -6145.8333 | Q31: 13557.107 | R31: -78125 | S31: -64567.893
D32: Q2 | F32: 3 | G32: 0 | H32: 152.46029 | I32: 127050.24 | J32: 36.179126 | K32: 30149.272 | L32: 27134.344 | M32: -770.92295 | N32: 123264.39 | O32: -10000 | P32: -6145.8333 | Q32: 107118.56 | R32: -78125 | S32: 28993.561
D33: Q3 | F33: 3 | G33: 0 | H33: 154.33132 | I33: 128609.44 | J33: 36.314041 | K33: 30261.701 | L33: 27235.531 | M33: -779.22483 | N33: 124804.04 | O33: -10000 | P33: -6145.8333 | Q33: 108658.21 | R33: -78125 | S33: 30533.207
D34: Q4 | F34: 3 | G34: 0 | H34: 156.22531 | I34: 130187.76 | J34: 36.449459 | K34: 30374.55 | L34: 27337.095 | M34: -787.62427 | N34: 126362.68 | O34: -10000 | P34: -6145.8333 | Q34: 110216.85 | R34: -78125 | S34: 32091.848
C35: Upside Total | F35: 11 | G35: 1 | H35: 613.62888 | I35: 427854.31 | J35: 144.98734 | K35: 120822.78 | L35: 99740.504 | M35: -2637.9741 | N35: 404134.06 | O35: -40000 | P35: -24583.333 | Q35: 339550.72 | R35: -312500 | S35: 27050.723
C36: Downside | D36: Q1 | F36: 1 | G36: 1 | H36: 150 | I36: 0 | J36: 36.103451 | K36: 30086.209 | L36: 7040.2503 | M36: -140.80501 | N36: -23186.764 | O36: -10000 | P36: -6145.8333 | Q36: -39332.597 | R36: -84375 | S36: -123707.6
D37: Q2 | F37: 3 | G37: 0 | H37: 150 | I37: 125000 | J37: 36.415293 | K37: 30346.077 | L37: 21242.254 | M37: -2924.8451 | N37: 112971.33 | O37: -10000 | P37: -6145.8333 | Q37: 96825.498 | R37: -84375 | S37: 12450.498
D38: Q3 | F38: 3 | G38: 0 | H38: 150 | I38: 125000 | J38: 36.729828 | K38: 30608.19 | L38: 21425.733 | M38: -2928.5147 | N38: 112889.03 | O38: -10000 | P38: -6145.8333 | Q38: 96743.195 | R38: -84375 | S38: 12368.195
D39: Q4 | F39: 3 | G39: 0 | H39: 150 | I39: 125000 | J39: 37.04708 | K39: 30872.567 | L39: 21610.797 | M39: -2932.2159 | N39: 112806.01 | O39: -10000 | P39: -6145.8333 | Q39: 96660.181 | R39: -84375 | S39: 12285.181
C40: Downside Total | F40: 10 | G40: 1 | H40: 600 | I40: 375000 | J40: 146.29565 | K40: 121913.04 | L40: 71319.034 | M40: -8926.3807 | N40: 315479.61 | O40: -40000 | P40: -24583.333 | Q40: 250896.28 | R40: -337500 | S40: -86603.723
F44: Occupied_ | G44: FreeRent_ | H44: Rent_psf_pa_ | I44: Base_Rent_ | J44: Expense_psf_pa_ | K44: OpEx_ | L44: Recoveries_ | M44: Bad_Debt_ | N44: NOI_pre_Amort_ | O44: TI_Amort_ | P44: LC_Amort_ | Q44: NOI_ | R44: Interest_Expense_ | S44: AFFO_
C45: Base | D45: 1 | E45: 45658 | F45: 0 | G45: 0 | H45: 50 | I45: 0 | J45: 12 | K45: 10000 | L45: 0 | M45: 0 | N45: -10000 | O45: -3333.3333 | P45: -2048.6111 | Q45: -15381.944 | R45: -26041.667 | S45: -41423.611
D46: 2 | E46: 45689 | F46: 1 | G46: 1 | H46: 50.123313 | I46: 0 | J46: 12.024718 | K46: 10020.598 | L46: 8016.4787 | M46: -80.164787 | N46: -2084.2845 | O46: -3333.3333 | P46: -2048.6111 | Q46: -7466.2289 | R46: -26041.667 | S46: -33507.896
D47: 3 | E47: 45717 | F47: 1 | G47: 0 | H47: 50.246931 | I47: 41872.443 | J47: 12.049487 | K47: 10041.239 | L47: 8032.9913 | M47: -499.05434 | N47: 39365.14 | O47: -3333.3333 | P47: -2048.6111 | Q47: 33983.196 | R47: -26041.667 | S47: 7941.5293
D48: 4 | E48: 45748 | F48: 1 | G48: 0 | H48: 50.370854 | I48: 41975.711 | J48: 12.074307 | K48: 10061.922 | L48: 8049.538 | M48: -500.25249 | N48: 39463.074 | O48: -3333.3333 | P48: -2048.6111 | Q48: 34081.13 | R48: -26041.667 | S48: 8039.4632
...

Sheet Timeline
A1: Month_Index | B1: Month_Start
A2: 1 | B2: =EDATE(Inputs!$B$3,ROW()-2) -> 45658
A3: 2 | B3: =EDATE(Inputs!$B$3,ROW()-2) -> 45689
A4: 3 | B4: =EDATE(Inputs!$B$3,ROW()-2) -> 45717
A5: 4 | B5: =EDATE(Inputs!$B$3,ROW()-2) -> 45748
A6: 5 | B6: =EDATE(Inputs!$B$3,ROW()-2) -> 45778
A7: 6 | B7: =EDATE(Inputs!$B$3,ROW()-2) -> 45809
A8: 7 | B8: =EDATE(Inputs!$B$3,ROW()-2) -> 45839
A9: 8 | B9: =EDATE(Inputs!$B$3,ROW()-2) -> 45870
A10: 9 | B10: =EDATE(Inputs!$B$3,ROW()-2) -> 45901
A11: 10 | B11: =EDATE(Inputs!$B$3,ROW()-2) -> 45931
A12: 11 | B12: =EDATE(Inputs!$B$3,ROW()-2) -> 45962
A13: 12 | B13: =EDATE(Inputs!$B$3,ROW()-2) -> 45992

Sheet Sens_RG
A1: Rent Growth (Annual_Rent_Growth_pct) Sensitivity
A4: Candidate | B4: Year_NOI_pre_Amort | C4: Year_AFFO | D4: ΔNOI vs Base | E4: Δ% vs Base
A5: 0 | B5: 379335.28 | C5: 2251.9418 | D5: =B5-INDEX(B$4:B$10, MATCH($A$7, A$4:A$10, 0)) -> -6668.1919 | E5: =B5/INDEX(B$4:B$10, MATCH($A$7, A$4:A$10, 0))-1 -> -0.017274953 | F5: =D5-INDEX(D$4:D$10, MATCH($A$7, A$4:A$10, 0)) -> -6668.1919
A6: 0.02 | B6: 383788.42 | C6: 6705.0904 | D6: =B6-INDEX(B$4:B$10, MATCH($A$7, A$4:A$10, 0)) -> -2215.0432 | E6: =B6/INDEX(B$4:B$10, MATCH($A$7, A$4:A$10, 0))-1 -> -0.0057384025
A7: 0.03 | B7: 386003.47 | C7: 8920.1337 | D7: =B7-INDEX(B$4:B$10, MATCH($A$7, A$4:A$10, 0)) -> 0 | E7: =B7/INDEX(B$4:B$10, MATCH($A$7, A$4:A$10, 0))-1 -> 0
A8: 0.04 | B8: 388210.97 | C8: 11127.637 | D8: =B8-INDEX(B$4:B$10, MATCH($A$7, A$4:A$10, 0)) -> 2207.5032 | E8: =B8/INDEX(B$4:B$10, MATCH($A$7, A$4:A$10, 0))-1 -> 0.0057188689
A9: 0.05 | B9: 390411.04 | C9: 13327.707 | D9: =B9-INDEX(B$4:B$10, MATCH($A$7, A$4:A$10, 0)) -> 4407.5736 | E9: =B9/INDEX(B$4:B$10, MATCH($A$7, A$4:A$10, 0))-1 -> 0.011418482
A10: 0.06 | B10: 392603.78 | C10: 15520.449 | D10: =B10-INDEX(B$4:B$10, MATCH($A$7, A$4:A$10, 0)) -> 6600.3157 | E10: =B10/INDEX(B$4:B$10, MATCH($A$7, A$4:A$10, 0))-1 -> 0.01709911

Sheet Sens_DT
A1: Downtime (Downtime_Months) Sensitivity
A4: Candidate | B4: Year_NOI_pre_Amort | C4: Year_AFFO | D4: ΔNOI vs Base | E4: Δ% vs Base
A5: 0 | B5: 435275.2 | C5: 78123.484 | D5: =B5-INDEX(B$4:B$10, MATCH($A$6, A$4:A$10, 0)) -> 49271.734 | E5: =B5/INDEX(B$4:B$10, MATCH($A$6, A$4:A$10, 0))-1 -> 0.12764583
A6: 1 | B6: 386003.47 | C6: 29269.445 | D6: =B6-INDEX(B$4:B$10, MATCH($A$6, A$4:A$10, 0)) -> 0 | E6: =B6/INDEX(B$4:B$10, MATCH($A$6, A$4:A$10, 0))-1 -> 0
A7: 2 | B7: 336613.43 | C7: -19701.863 | D7: =B7-INDEX(B$4:B$10, MATCH($A$6, A$4:A$10, 0)) -> -49390.032 | E7: =B7/INDEX(B$4:B$10, MATCH($A$6, A$4:A$10, 0))-1 -> -0.1279523
A8: 3 | B8: 287104.82 | C8: -68790.721 | D8: =B8-INDEX(B$4:B$10, MATCH($A$6, A$4:A$10, 0)) -> -98898.648 | E8: =B8/INDEX(B$4:B$10, MATCH($A$6, A$4:A$10, 0))-1 -> -0.25621181

Sheet Sens_EG
A1: Expense Growth (Expense_Growth_pct) Sensitivity
A4: Candidate | B4: Year_NOI_pre_Amort | C4: Year_AFFO | D4: ΔNOI vs Base | E4: Δ% vs Base
A5: 0.015 | B5: 386117.05 | C5: 29383.031 | D5: =B5-INDEX(B$4:B$10, MATCH($A$6, A$4:A$10, 0)) -> 113.58621 | E5: =B5/INDEX(B$4:B$10, MATCH($A$6, A$4:A$10, 0))-1 -> 0.00029426215
A6: 0.025 | B6: 386003.47 | C6: 29269.445 | D6: =B6-INDEX(B$4:B$10, MATCH($A$6, A$4:A$10, 0)) -> 0 | E6: =B6/INDEX(B$4:B$10, MATCH($A$6, A$4:A$10, 0))-1 -> 0
A7: 0.035 | B7: 385890.28 | C7: 29156.257 | D7: =B7-INDEX(B$4:B$10, MATCH($A$6, A$4:A$10, 0)) -> -113.1881 | E7: =B7/INDEX(B$4:B$10, MATCH($A$6, A$4:A$10, 0))-1 -> -0.00029323079

Sheet Sens_RR
A1: Reference Rate (Reference_Rate_pct) Sensitivity
A4: Candidate | B4: Year_NOI_pre_Amort | C4: Year_AFFO | D4: ΔNOI vs Base | E4: Δ% vs Base | F4: ΔAFFO vs Base | G4: Δ% vs Base
A5: 0.03 | B5: 386003.47 | C5: 79269.445 | D5: =B5-INDEX(B$4:B$10, MATCH($A$7, A$4:A$10, 0)) -> 0 | E5: =B5/INDEX(B$4:B$10, MATCH($A$7, A$4:A$10, 0))-1 -> 0 | F5: =C5-INDEX(C$4:C$10, MATCH($A$7, A$4:A$10, 0)) -> 50000 | G5: =C5/INDEX(C$4:C$10, MATCH($A$7, A$4:A$10, 0))-1 -> 1.7082661
A6: 0.04 | B6: 386003.47 | C6: 54269.445 | D6: =B6-INDEX(B$4:B$10, MATCH($A$7, A$4:A$10, 0)) -> 0 | E6: =B6/INDEX(B$4:B$10, MATCH($A$7, A$4:A$10, 0))-1 -> 0 | F6: =C6-INDEX(C$4:C$10, MATCH($A$7, A$4:A$10, 0)) -> 25000 | G6: =C6/INDEX(C$4:C$10, MATCH($A$7, A$4:A$10, 0))-1 -> 0.85413304
A7: 0.05 | B7: 386003.47 | C7: 29269.445 | D7: =B7-INDEX(B$4:B$10, MATCH($A$7, A$4:A$10, 0)) -> 0 | E7: =B7/INDEX(B$4:B$10, MATCH($A$7, A$4:A$10, 0))-1 -> 0 | F7: =C7-INDEX(C$4:C$10, MATCH($A$7, A$4:A$10, 0)) -> 0 | G7: =C7/INDEX(C$4:C$10, MATCH($A$7, A$4:A$10, 0))-1 -> 0
A8: 0.06 | B8: 386003.47 | C8: 4269.4449 | D8: =B8-INDEX(B$4:B$10, MATCH($A$7, A$4:A$10, 0)) -> 0 | E8: =B8/INDEX(B$4:B$10, MATCH($A$7, A$4:A$10, 0))-1 -> 0 | F8: =C8-INDEX(C$4:C$10, MATCH($A$7, A$4:A$10, 0)) -> -25000 | G8: =C8/INDEX(C$4:C$10, MATCH($A$7, A$4:A$10, 0))-1 -> -0.85413304
A9: 0.07 | B9: 386003.47 | C9: -20730.555 | D9: =B9-INDEX(B$4:B$10, MATCH($A$7, A$4:A$10, 0)) -> 0 | E9: =B9/INDEX(B$4:B$10, MATCH($A$7, A$4:A$10, 0))-1 -> 0 | F9: =C9-INDEX(C$4:C$10, MATCH($A$7, A$4:A$10, 0)) -> -50000 | G9: =C9/INDEX(C$4:C$10, MATCH($A$7, A$4:A$10, 0))-1 -> -1.7082661

Sheet Mapping
A1: 字段/公式 | B1: 说明 | E1: Rent Roll | F1: Inputs | G1: 取值/公式示例 | H1: 备注
A2: Occupied | B2: Month_Index>=Downtime+1, Month_Index<=Downtime+Lease_Term | E2: Tenant | F2: Tenant_ID | H2: 可与 Suite 拼接保证唯一
A3: FreeRent | B3: Month_Index>=Downtime+1, Month_Index<=Downtime+Free_Rent | E3: GLA_sqft | F3: GLA_sqft | H3: 单位一致
A4: Rent_psf_pa | B4: Monthly compounding annual rent growth | E4: Lease_Start | F4: Analysis_Start | H4: 若项目统一起算，可设全局起算月
A5: Base_Rent | B5: Occupied*(1-FreeRent)*(Rent_psf_pa/12)*GLA_sqft | E5: Lease_Term_Months | F5: Lease_Term_Months | H5: 月数
A6: Expense_psf_pa | B6: Monthly compounding Expense_Base_psf_pa | E6: Free_Rent_Months | F6: Free_Rent_Months | H6: 月数
A7: OpEx | B7: (Expense_psf_pa/12)*GLA_sqft | E7: Downtime_Months | F7: Downtime_Months | H7: 起租前空置
A8: Recoveries | B8: Occupied OpEx with CAM_Recovery | E8: Base_Rent_psf_pa_Y1 | F8: Base_Rent_psf_pa | H8: $/psf/年
A9: Bad_Debt | B9: -(Base_Rent+Recoveries)*Bad_Debt_pct_of_Rent | E9: Annual_Rent_Growth_% | F9: Annual_Rent_Growth_pct | H9: 小数 0–0.05
A10: NOI_pre_Amort | B10: Base_Rent + Recoveries + Bad_Debt - OpEx | E10: Expense_Structure | F10: Expense_Model | G10: “NNN/Modified/Gross” | H10: 影响 Recoveries 模块
A11: TI_Amort | B11: only for TI_Amort_Years, evenly amortized | C11: Smooths large upfront costs into uniform monthly charges to show stabilized NOI/AFFO impact. | E11: Base_Year | F11: Base_Year | H11: Modified/Gross 常用
A12: LC_Amort | B12: only for LC_Amort_Years, evenly amortized | C12: Aligns one-off leasing costs with the economic benefit period of the lease. | E12: Expense_Stop_psf | F12: Expense_Stop_psf | H12: 超出由租户承担
A13: NOI | B13: NOI_pre_Amort + TI_Amort + LC_Amort | E13: CAM_Cap_% | F13: CAM_Cap_pct | H13: Recoveries 上限
A14: Interest_Expense | B14: Debt_Balance with Eff_rate per month | E14: TI_$psf | F14: TI_$psf | H14: 一次性或摊销
A15: AFFO | B15: NOI + Interest_Expense | E15: LC_%_of_Y1_Rent | F15: LC_%_of_Year1_Rent | H15: % of Year1 Rent
E16: Percent_Rent | F16: Percent_Rent_Terms | H16: 进入可变租金模块
E17: Bad_Debt_Flag | F17: Bad_Debt_Assumption | G17: IF(Flag=1,0.02,0.01) | H17: 口径示例

Sheet Clauses Checklist
A1: Exception Clauses Checklist
A2: To pre-screen high-risk or cash-flow-uncertain lease clauses before reporting, and to parameterize their impacts in the model as Overrides. Each item below should be summarized in one to two lines in your Issues Log.
A3: > Workflow：identify clauses → Issues Log → confirm with Leasing/Legal → parameterized in Overrides（impanct on: Occupied/FreeRent/Base_Rent/Recoveries/TI/LC/Bad_Debt
A5: Co-tenancy | B5: 共同租赁/锚店业绩触发 | C5: set Base_Rent = 0 or apply a discount factor | D5: If an anchor tenant closes or its sales drop below the defined threshold, the tenant may reduce rent, enter free-rent period, or terminate the lease.
A6: Exclusive Use | B6: 独家经营权 | C6: increase Downtime or reduce Rent_Growth | D6: Prohibits the landlord from leasing to competing tenants. This reduces leasing flexibility and may extend downtime for vacant space.
A7: Kick-out / Early Termination | B7: 提前解约权 | C7: set Occupied = 0 and create a second downtime period | D7: Allows termination if sales fall below a threshold (e.g., after 36 months).
A8: Side Letter | B8: 边函 | C8: add one-off cash outflow or extend the Free_Rent months | D8: Separate agreement granting extra free rent, tenant allowance, signage rights, or marketing support not stated in the main lease.
A9: SNDA | C9: under stress scenarios, raise Bad_Debt or add a termination probability. | D9: Without an SNDA, foreclosure or lender enforcement may void or renegotiate leases.
A10: ROFR | C10: expansion rent uplift or extend leasing lead time. | D10: tenant can match any third-party offer
A11: ROFO | D11: tenant must be offered first before marketing externally.
A12: Base Year / Expense Stop | C12: Recovery = Share × MAX(0, OpEx – Base/Stop) × GLA. | D12: Tenant reimburses operating expenses only above the base year or stop level.
A13: CAM Cap / Collar | C13: Recovery = MIN( MAX(Raw_Recovery, Prior × (1 – Floor%)), Prior × (1 + Cap%) ). | D13: Places an annual upper (cap) or band (collar) limit on recoverable expenses, reducing recovery elasticity.
A14: Go-Dark / Continuous Operation | C14: apply secondary increases to other tenants’ Downtime or Bad_Debt. | D14: Permits tenant to cease operations while continuing rent payments. This can reduce foot traffic and trigger other tenants’ co-tenancy clauses.
A15: Percentage Rent | C15: keep a separate variable-rent module, activated only when Sales > Breakpoint. | D15: Rent linked to sales above a threshold; should not be straight-lined or recognized before threshold attainment.
